Workbook

Sheet Instructions
B2: 12.1 Blood Death Knight Calculation Spreadsheet
B3: By Kyrasis - Area 52 (Discord: Kyrasis)
B5: Disclaimer:
B6: While DPS is also calculated and can be used to gather useful for relative evaluations, an up-to-date simcraft module should be superior for absolute DPS evaluation in specific encounters. This is a theorycrafting tool for primarily assessing mitigation and is intended/recommended to advanced users with upfront class knowledge, since it can be difficult to use correctly and good outputs are reasonably dependent on good inputs. If you have any specific questions regarding this spreadsheet, please DM Kyrasis as your first line of support.
B8: General Information:
B9: This spreadsheet was created to gather information on stat weights, items, talents, races, and runeforging; particularly with regards to mitigation, since it's an essential, but often ignored, aspect of blood theorycrafting. This spreadsheet calculates Mitigation, DPS, and Effective HP stat weights based on input character information and steady-state assumptions. Mitigation, itself, is measured by calculating how many points of damage can be taken per point of external healing required (from a healer, for instance) in order to survive indefinitely; all effects are generally averaged for the purposes of these calculations and several variables are held constant (such as incoming damage composition, damage taken, and overhealing). The results from this calculation are only as relevent as the assumptions used. As a tank, you'll be placed in a number of different scenarios, so results from a single scenario may not be representative of others. You'll first create a profile for your character, as is, which will result in some general stat weights. If you want to view the effects of using different items, talents, runeforges, or races, changes can be entered into a secondary profile which can be used for direct comparison.
B11: Instructions:
B12: 1. Make a copy of this spreadsheet.
B13: 2. Open the "Data Input" Sheet.
B14: 3. Under "Baseline Character Inputs" complete the "Character Attributes" section with information straight from your character sheet with no buffs active, unless you want to manually account for consumables.
B15: 4. Complete the "Runeforging" section using "1" for the selected Runeforge and "0" for the Runeforge not selected.
B16: 5. Complete the "Race" section using "1" for the selected Race and "0" for the Race not selected. Additional options are noted where applicable.
... B29: A special thanks to Thorlefulz, Mythie, and Terra for helping out with this spreadsheet

Sheet Inputs
B2: Inputs
B4: Baseline | G4: Comparison
B6: Character Attributes | C6: Character Sheet | G6: Character Attributes | H6: Character Sheet | I6: Differentials
B7: Armor | C7: 3852 | G7: Armor
B8: Strength | C8: 2672 | G8: Strength
B9: Stamina | C9: 77197 | G9: Stamina
B10: Critical Strike Rating | C10: 778.5 | G10: Critical Strike Rating
B11: Haste Rating | C11: 1053.5 | G11: Haste Rating
B12: Versatility Rating | C12: 1514.5 | G12: Versatility Rating
B13: Mastery Rating | C13: 479.5 | G13: Mastery Rating
B14: Leech Rating | C14: 0 | G14: Leech Rating
B15: Avoidance Rating | C15: 0 | G15: Avoidance Rating
B16: Base Weapon DPS | C16: 151.4 | G16: Base Weapon DPS
B17: Base Weapon Speed | C17: 3.6 | G17: Base Weapon Speed
B19: Runeforging | G19: Runeforging
B20: Razorice | C20: Sanguination | D20: Spellwarding | E20: Apocalypse | G20: Razorice | H20: Sanguination | I20: Spellwarding | J20: Apocalypse
C21: 1
B22: Fallen Crusader | C22: Stoneskin Gargoyle | D22: Unending Thirst | G22: Fallen Crusader | H22: Stoneskin Gargoyle | I22: Unending Thirst
B25: Race | G25: Race
B26: Orc | C26: 0 | D26: Pandaren | E26: 0 | G26: Orc | I26: Pandaren
B27: Undead | C27: 0 | D27: Nightborne | E27: 0 | G27: Undead | I27: Nightborne
B28: Tauren | C28: 0 | D28: Highmountain | E28: 0 | G28: Tauren | I28: Highmountain
B29: Troll | C29: 0 | D29: Mag'har | E29: 0 | G29: Troll | I29: Mag'har
B30: Blood Elf | C30: 0 | D30: Zandalari | E30: 0 | G30: Blood Elf | I30: Zandalari
B31: Goblin | C31: 0 | D31: Vulpera | E31: 0 | G31: Goblin | I31: Vulpera
B32: Human | C32: 0 | D32: Void Elf | E32: 0 | G32: Human | I32: Void Elf
B33: Dwarf | C33: 0 | D33: Lightforged Draenei | E33: 0 | G33: Dwarf | I33: Lightforged Draenei
B34: Night Elf | C34: 0 | D34: Dark Iron Dwarf | E34: 0 | G34: Night Elf | I34: Dark Iron Dwarf
B35: Gnome | C35: 0 | D35: Kul Tiran | E35: 0 | G35: Gnome | I35: Kul Tiran
B36: Draenei | C36: 0 | D36: Mechagnome | E36: 0 | G36: Draenei | I36: Mechagnome
B37: Worgen | C37: 0 | G37: Worgen | K37: =K38
B39: Death Knight Talents | C39: Rank | D39: Variable | G39: Death Knight Talents | H39: Rank | I39: Variable
A40: Row 1 | B40: Icebound Fortitude | C40: 1 | F40: Row 1 | G40: Icebound Fortitude
B41: Death Strike | C41: 1 | G41: Death Strike
B42: Raise Dead | C42: 1 | G42: Raise Dead
A43: Row 2 | B43: Runic Attenuation | C43: 1 | F43: Row 2 | G43: Runic Attenuation
B44: Improved Death Strike | C44: 1 | G44: Improved Death Strike
B45: Cleaving Strikes | C45: 1 | G45: Cleaving Strikes
A46: Row 3 | B46: Mind Freeze | C46: 1 | D46: 0 | F46: Row 3 | G46: Mind Freeze
B47: Blinding Sleet | C47: 1 | G47: Blinding Sleet
...

Sheet Outputs
B2: Data Outputs
B4: Baseline Stat Weights | F4: Performance Indicators
B6: Mitigation Stat Weights | C6: Raw | D6: Normalized | F6: Performance Measures | G6: Baseline | H6: Comparison | I6: Differential
B7: Armor | C7: =IF(OR(N('+Armor'!$N$15)=0,N(Baseline!$N$15)=0),((1-(('+Armor'!T10-'+Armor'!U10-'+Armor'!V10-'+Armor'!W10)*(1-'+Armor'!$T$76*(10+2*'+Armor'!C92))+('+Armor'!T10-'+Armor'!U10-'+Armor'!V10-'+Armor'!W10*(1.3+0.05*'+Armor'!C92))*'+Armor'!$T$76*(10+2*'+Armor'!C92))/'+Armor'!O10*Baseline!T10/'+Armor'!T10)-(1-((Baseline!T10-Baseline!U10-Baseline!V10-Baseline!W10)*(1-Baseline!$T$76*(10+2*Baseline!C92))+(Baseline!T10-Baseline!U10-Baseline!V10-Baseline!W10*(1.3+0.05*Baseline!C92))*Baseline!$T$76*(10+2*Baseline!C92))/Baseline!O10))/(1-((Baseline!T10-Baseline!U10-Baseline!V10-Baseline!W10)*(1-Baseline!$T$76*(10+2*Baseline!C92))+(Baseline!T10-Baseline!U10-Baseline!V10-Baseline!W10*(1.3+0.05*Baseline!C92))*Baseline!$T$76*(10+2*Baseline!C92))/Baseline!O10)/10,('+Armor'!$N$15-Baseline!$N$15)/10) -> 1.0267162e-06 | D7: =C7/MAX($C$7:$C$16) -> 0.10773169 | F7: Mitigation Factor | G7: =Baseline!N15 -> 0.99966202 | H7: =Comparison!N15 -> 0.99980942 | I7: ="("&ROUND(((1-((Comparison!T10-Comparison!U10-Comparison!V10-Comparison!W10)*(1-Comparison!$T$76*(10+2*Comparison!C92))+(Comparison!T10-Comparison!U10-Comparison!V10-Comparison!W10*(1.3+0.05*Comparison!C92))*(Comparison!$T$76*(10+2*Comparison!C92)))/Comparison!O10*Baseline!T10/Comparison!T10)-(1-((Baseline!T10-Baseline!U10-Baseline!V10-Baseline!W10)*(1-Baseline!$T$76*(10+2*Baseline!C92))+(Baseline!T10-Baseline!U10-Baseline!V10-Baseline!W10*(1.3+0.05*Baseline!C92))*(Baseline!$T$76*(10+2*Baseline!C92)))/Baseline!O10))/(1-((Baseline!T10-Baseline!U10-Baseline!V10-Baseline!W10)*(1-Baseline!$T$76*(10+2*Baseline!C92))+(Baseline!T10-Baseline!U10-Baseline!V10-Baseline!W10*(1.3+0.05*Baseline!C92))*(Baseline!$T$76*(10+2*Baseline!C92)))/Baseline!O10)%,2)&"%)" -> (0.01%)
B8: Strength | C8: =IF(OR(N('+Strength'!$N$15)=0,N(Baseline!$N$15)=0),((1-(('+Strength'!T10-'+Strength'!U10-'+Strength'!V10-'+Strength'!W10)*(1-'+Strength'!$T$76*(10+2*'+Strength'!C92))+('+Strength'!T10-'+Strength'!U10-'+Strength'!V10-'+Strength'!W10*(1.3+0.05*'+Strength'!C92))*'+Strength'!$T$76*(10+2*'+Strength'!C92))/'+Strength'!O10*Baseline!T10/'+Strength'!T10)-(1-((Baseline!T10-Baseline!U10-Baseline!V10-Baseline!W10)*(1-Baseline!$T$76*(10+2*Baseline!C92))+(Baseline!T10-Baseline!U10-Baseline!V10-Baseline!W10*(1.3+0.05*Baseline!C92))*Baseline!$T$76*(10+2*Baseline!C92))/Baseline!O10))/(1-((Baseline!T10-Baseline!U10-Baseline!V10-Baseline!W10)*(1-Baseline!$T$76*(10+2*Baseline!C92))+(Baseline!T10-Baseline!U10-Baseline!V10-Baseline!W10*(1.3+0.05*Baseline!C92))*Baseline!$T$76*(10+2*Baseline!C92))/Baseline!O10)/10,('+Strength'!$N$15-Baseline!$N$15)/10) -> 5.5891595e-06 | D8: =C8/MAX($C$7:$C$16) -> 0.58646157 | F8: Overall DPS | G8: =Baseline!O15 -> 324430.93 | H8: =Comparison!O15 -> 326198.05 | I8: =(H8-G8)/G8 -> 0.0054468098
B9: Stamina | C9: =IF(OR(N('+Stamina'!$N$15)=0,N(Baseline!$N$15)=0),((1-(('+Stamina'!T10-'+Stamina'!U10-'+Stamina'!V10-'+Stamina'!W10)*(1-'+Stamina'!$T$76*(10+2*'+Stamina'!C92))+('+Stamina'!T10-'+Stamina'!U10-'+Stamina'!V10-'+Stamina'!W10*(1.3+0.05*'+Stamina'!C92))*'+Stamina'!$T$76*(10+2*'+Stamina'!C92))/'+Stamina'!O10*Baseline!T10/'+Stamina'!T10)-(1-((Baseline!T10-Baseline!U10-Baseline!V10-Baseline!W10)*(1-Baseline!$T$76*(10+2*Baseline!C92))+(Baseline!T10-Baseline!U10-Baseline!V10-Baseline!W10*(1.3+0.05*Baseline!C92))*Baseline!$T$76*(10+2*Baseline!C92))/Baseline!O10))/(1-((Baseline!T10-Baseline!U10-Baseline!V10-Baseline!W10)*(1-Baseline!$T$76*(10+2*Baseline!C92))+(Baseline!T10-Baseline!U10-Baseline!V10-Baseline!W10*(1.3+0.05*Baseline!C92))*Baseline!$T$76*(10+2*Baseline!C92))/Baseline!O10)/10,('+Stamina'!$N$15-Baseline!$N$15)/10) -> 4.1861552e-08 | D9: =C9/MAX($C$7:$C$16) -> 0.0043924656 | F9: Priority DPS | G9: =Baseline!P15 -> 112067.47 | H9: =Comparison!P15 -> 111420.21 | I9: =(H9-G9)/G9 -> -0.0057756443
B10: Critical Strike | C10: =IF(OR(N('+Critical Strike'!$N$15)=0,N(Baseline!$N$15)=0),((1-(('+Critical Strike'!T10-'+Critical Strike'!U10-'+Critical Strike'!V10-'+Critical Strike'!W10)*(1-'+Critical Strike'!$T$76*(10+2*'+Critical Strike'!C92))+('+Critical Strike'!T10-'+Critical Strike'!U10-'+Critical Strike'!V10-'+Critical Strike'!W10*(1.3+0.05*'+Critical Strike'!C92))*'+Critical Strike'!$T$76*(10+2*'+Critical Strike'!C92))/'+Critical Strike'!O10*Baseline!T10/'+Critical Strike'!T10)-(1-((Baseline!T10-Baseline!U10-Baseline!V10-Baseline!W10)*(1-Baseline!$T$76*(10+2*Baseline!C92))+(Baseline!T10-Baseline!U10-Baseline!V10-Baseline!W10*(1.3+0.05*Baseline!C92))*Baseline!$T$76*(10+2*Baseline!C92))/Baseline!O10))/(1-((Baseline!T10-Baseline!U10-Baseline!V10-Baseline!W10)*(1-Baseline!$T$76*(10+2*Baseline!C92))+(Baseline!T10-Baseline!U10-Baseline!V10-Baseline!W10*(1.3+0.05*Baseline!C92))*Baseline!$T$76*(10+2*Baseline!C92))/Baseline!O10)/10,('+Critical Strike'!$N$15-Baseline!$N$15)/10) -> 4.4658048e-06 | D10: =C10/MAX($C$7:$C$16) -> 0.46858975 | F10: Reliable Effective Health | G10: =Baseline!Q15 -> 9369364.5 | H10: =Comparison!Q15 -> 9364180.2 | I10: =(H10-G10)/G10 -> -0.00055332346
B11: Haste | C11: =IF(OR(N('+Haste'!$N$15)=0,N(Baseline!$N$15)=0),((1-(('+Haste'!T10-'+Haste'!U10-'+Haste'!V10-'+Haste'!W10)*(1-'+Haste'!$T$76*(10+2*'+Haste'!C92))+('+Haste'!T10-'+Haste'!U10-'+Haste'!V10-'+Haste'!W10*(1.3+0.05*'+Haste'!C92))*'+Haste'!$T$76*(10+2*'+Haste'!C92))/'+Haste'!O10*Baseline!T10/'+Haste'!T10)-(1-((Baseline!T10-Baseline!U10-Baseline!V10-Baseline!W10)*(1-Baseline!$T$76*(10+2*Baseline!C92))+(Baseline!T10-Baseline!U10-Baseline!V10-Baseline!W10*(1.3+0.05*Baseline!C92))*Baseline!$T$76*(10+2*Baseline!C92))/Baseline!O10))/(1-((Baseline!T10-Baseline!U10-Baseline!V10-Baseline!W10)*(1-Baseline!$T$76*(10+2*Baseline!C92))+(Baseline!T10-Baseline!U10-Baseline!V10-Baseline!W10*(1.3+0.05*Baseline!C92))*Baseline!$T$76*(10+2*Baseline!C92))/Baseline!O10)/10,('+Haste'!$N$15-Baseline!$N$15)/10) -> 3.1174989e-06 | D11: =C11/MAX($C$7:$C$16) -> 0.32711417 | F11: Reliable and Controllable Effective Health | G11: =Baseline!R15 -> 11517617 | H11: =Comparison!R15 -> 11592261 | I11: =(H11-G11)/G11 -> 0.006480929
B12: Versatility | C12: =IF(OR(N('+Versatility'!$N$15)=0,N(Baseline!$N$15)=0),((1-(('+Versatility'!T10-'+Versatility'!U10-'+Versatility'!V10-'+Versatility'!W10)*(1-'+Versatility'!$T$76*(10+2*'+Versatility'!C92))+('+Versatility'!T10-'+Versatility'!U10-'+Versatility'!V10-'+Versatility'!W10*(1.3+0.05*'+Versatility'!C92))*'+Versatility'!$T$76*(10+2*'+Versatility'!C92))/'+Versatility'!O10*Baseline!T10/'+Versatility'!T10)-(1-((Baseline!T10-Baseline!U10-Baseline!V10-Baseline!W10)*(1-Baseline!$T$76*(10+2*Baseline!C92))+(Baseline!T10-Baseline!U10-Baseline!V10-Baseline!W10*(1.3+0.05*Baseline!C92))*Baseline!$T$76*(10+2*Baseline!C92))/Baseline!O10))/(1-((Baseline!T10-Baseline!U10-Baseline!V10-Baseline!W10)*(1-Baseline!$T$76*(10+2*Baseline!C92))+(Baseline!T10-Baseline!U10-Baseline!V10-Baseline!W10*(1.3+0.05*Baseline!C92))*Baseline!$T$76*(10+2*Baseline!C92))/Baseline!O10)/10,('+Versatility'!$N$15-Baseline!$N$15)/10) -> 7.4539218e-06 | D12: =C12/MAX($C$7:$C$16) -> 0.78212809 | F12: Unreliable Effective Health | G12: =Baseline!S15 -> 21754755 | H12: =Comparison!S15 -> 21816643 | I12: =(H12-G12)/G12 -> 0.0028447697
B13: Mastery | C13: =IF(OR(N('+Mastery'!$N$15)=0,N(Baseline!$N$15)=0),((1-(('+Mastery'!T10-'+Mastery'!U10-'+Mastery'!V10-'+Mastery'!W10)*(1-'+Mastery'!$T$76*(10+2*'+Mastery'!C92))+('+Mastery'!T10-'+Mastery'!U10-'+Mastery'!V10-'+Mastery'!W10*(1.3+0.05*'+Mastery'!C92))*'+Mastery'!$T$76*(10+2*'+Mastery'!C92))/'+Mastery'!O10*Baseline!T10/'+Mastery'!T10)-(1-((Baseline!T10-Baseline!U10-Baseline!V10-Baseline!W10)*(1-Baseline!$T$76*(10+2*Baseline!C92))+(Baseline!T10-Baseline!U10-Baseline!V10-Baseline!W10*(1.3+0.05*Baseline!C92))*Baseline!$T$76*(10+2*Baseline!C92))/Baseline!O10))/(1-((Baseline!T10-Baseline!U10-Baseline!V10-Baseline!W10)*(1-Baseline!$T$76*(10+2*Baseline!C92))+(Baseline!T10-Baseline!U10-Baseline!V10-Baseline!W10*(1.3+0.05*Baseline!C92))*Baseline!$T$76*(10+2*Baseline!C92))/Baseline!O10)/10,('+Mastery'!$N$15-Baseline!$N$15)/10) -> 9.5303083e-06 | D13: =C13/MAX($C$7:$C$16) -> 1
B14: Leech | C14: =IF(OR(N('+Leech'!$N$15)=0,N(Baseline!$N$15)=0),((1-(('+Leech'!T10-'+Leech'!U10-'+Leech'!V10-'+Leech'!W10)*(1-'+Leech'!$T$76*(10+2*'+Leech'!C92))+('+Leech'!T10-'+Leech'!U10-'+Leech'!V10-'+Leech'!W10*(1.3+0.05*'+Leech'!C92))*'+Leech'!$T$76*(10+2*'+Leech'!C92))/'+Leech'!O10*Baseline!T10/'+Leech'!T10)-(1-((Baseline!T10-Baseline!U10-Baseline!V10-Baseline!W10)*(1-Baseline!$T$76*(10+2*Baseline!C92))+(Baseline!T10-Baseline!U10-Baseline!V10-Baseline!W10*(1.3+0.05*Baseline!C92))*Baseline!$T$76*(10+2*Baseline!C92))/Baseline!O10))/(1-((Baseline!T10-Baseline!U10-Baseline!V10-Baseline!W10)*(1-Baseline!$T$76*(10+2*Baseline!C92))+(Baseline!T10-Baseline!U10-Baseline!V10-Baseline!W10*(1.3+0.05*Baseline!C92))*Baseline!$T$76*(10+2*Baseline!C92))/Baseline!O10)/10,('+Leech'!$N$15-Baseline!$N$15)/10) -> 1.8127313e-06 | D14: =C14/MAX($C$7:$C$16) -> 0.19020699
B15: Avoidance | C15: =IF(OR(N('+Avoidance'!$N$15)=0,N(Baseline!$N$15)=0),((1-(('+Avoidance'!T10-'+Avoidance'!U10-'+Avoidance'!V10-'+Avoidance'!W10)*(1-'+Avoidance'!$T$76*(10+2*'+Avoidance'!C92))+('+Avoidance'!T10-'+Avoidance'!U10-'+Avoidance'!V10-'+Avoidance'!W10*(1.3+0.05*'+Avoidance'!C92))*'+Avoidance'!$T$76*(10+2*'+Avoidance'!C92))/'+Avoidance'!O10*Baseline!T10/'+Avoidance'!T10)-(1-((Baseline!T10-Baseline!U10-Baseline!V10-Baseline!W10)*(1-Baseline!$T$76*(10+2*Baseline!C92))+(Baseline!T10-Baseline!U10-Baseline!V10-Baseline!W10*(1.3+0.05*Baseline!C92))*Baseline!$T$76*(10+2*Baseline!C92))/Baseline!O10))/(1-((Baseline!T10-Baseline!U10-Baseline!V10-Baseline!W10)*(1-Baseline!$T$76*(10+2*Baseline!C92))+(Baseline!T10-Baseline!U10-Baseline!V10-Baseline!W10*(1.3+0.05*Baseline!C92))*Baseline!$T$76*(10+2*Baseline!C92))/Baseline!O10)/10,('+Avoidance'!$N$15-Baseline!$N$15)/10) -> 0 | D15: =C15/MAX($C$7:$C$16) -> 0
B16: Weapon DPS | C16: =IF(OR(N('+Weapon DPS'!$N$15)=0,N(Baseline!$N$15)=0),((1-(('+Weapon DPS'!T10-'+Weapon DPS'!U10-'+Weapon DPS'!V10-'+Weapon DPS'!W10)*(1-'+Weapon DPS'!$T$76*(10+2*'+Weapon DPS'!C92))+('+Weapon DPS'!T10-'+Weapon DPS'!U10-'+Weapon DPS'!V10-'+Weapon DPS'!W10*(1.3+0.05*'+Weapon DPS'!C92))*'+Weapon DPS'!$T$76*(10+2*'+Weapon DPS'!C92))/'+Weapon DPS'!O10*Baseline!T10/'+Weapon DPS'!T10)-(1-((Baseline!T10-Baseline!U10-Baseline!V10-Baseline!W10)*(1-Baseline!$T$76*(10+2*Baseline!C92))+(Baseline!T10-Baseline!U10-Baseline!V10-Baseline!W10*(1.3+0.05*Baseline!C92))*Baseline!$T$76*(10+2*Baseline!C92))/Baseline!O10))/(1-((Baseline!T10-Baseline!U10-Baseline!V10-Baseline!W10)*(1-Baseline!$T$76*(10+2*Baseline!C92))+(Baseline!T10-Baseline!U10-Baseline!V10-Baseline!W10*(1.3+0.05*Baseline!C92))*Baseline!$T$76*(10+2*Baseline!C92))/Baseline!O10)/10,('+Weapon DPS'!$N$15-Baseline!$N$15)/10) -> 1.6307413e-06 | D16: =C16/MAX($C$7:$C$16) -> 0.17111108
B17: Pawn String | C17: ="( Pawn: v1: ""BDK Mitigation"": Leech="&D14&", CritRating="&D10&", Dps="&D16&", Strength="&D8&", HasteRating="&D11&", MasteryRating="&D13&", Stamina="&D9&", Armor="&D7&", Versatility="&D12&" )" -> ( Pawn: v1: "BDK Mitigation": Leech=0.190206990482102, CritRating=0.468589748233894, Dps=0.171111075250752, Strength=0.586461567124541, HasteRating=0.327114172927727, MasteryRating=1, Stamina=0.00439246562690173, Armor=0.107731691752119, Versatility=0.782128089867699 )
B19: Overall DPS Stat Weights | C19: Raw | D19: Normalized
B20: Armor | C20: =('+Armor'!$O$15-Baseline!$O$15)/10 -> 0 | D20: =C20/MAX($C$20:$C$29) -> 0
B21: Strength | C21: =('+Strength'!$O$15-Baseline!$O$15)/10 -> 96.211805 | D21: =C21/MAX($C$20:$C$29) -> 0.20440387
B22: Stamina | C22: =('+Stamina'!$O$15-Baseline!$O$15)/10 -> 0 | D22: =C22/MAX($C$20:$C$29) -> 0
B23: Critical Strike | C23: =('+Critical Strike'!$O$15-Baseline!$O$15)/10 -> 63.016361 | D23: =C23/MAX($C$20:$C$29) -> 0.1338795
B24: Haste | C24: =('+Haste'!$O$15-Baseline!$O$15)/10 -> 71.461462 | D24: =C24/MAX($C$20:$C$29) -> 0.15182128
B25: Versatility | C25: =('+Versatility'!$O$15-Baseline!$O$15)/10 -> 47.664984 | D25: =C25/MAX($C$20:$C$29) -> 0.10126519
B26: Mastery | C26: =('+Mastery'!$O$15-Baseline!$O$15)/10 -> 59.179999 | D26: =C26/MAX($C$20:$C$29) -> 0.12572907
B27: Leech | C27: =('+Leech'!$O$15-Baseline!$O$15)/10 -> 0 | D27: =C27/MAX($C$20:$C$29) -> 0
B28: Avoidance | C28: =('+Avoidance'!$O$15-Baseline!$O$15)/10 -> 0 | D28: =C28/MAX($C$20:$C$29) -> 0
B29: Weapon DPS | C29: ='+Weapon DPS'!$O$15-Baseline!$O$15 -> 470.69464 | D29: =C29/MAX($C$20:$C$29) -> 1
B30: Pawn String | C30: ="( Pawn: v1: ""BDK Overall DPS"": Leech="&D27&", CritRating="&D23&", Dps="&D29&", Strength="&D21&", HasteRating="&D24&", MasteryRating="&D26&", Stamina="&D22&", Armor="&D20&", Versatility="&D25&" )" -> ( Pawn: v1: "BDK Overall DPS": Leech=0, CritRating=0.133879496504267, Dps=1, Strength=0.204403868746095, HasteRating=0.151821279689373, MasteryRating=0.125729070391317, Stamina=0, Armor=0, Versatility=0.101265194419826 )
B32: Priority DPS Stat Weights | C32: Raw | D32: Normalized
B33: Armor | C33: =('+Armor'!$P$15-Baseline!$P$15)/10 -> 0 | D33: =C33/MAX($C$33:$C$42) -> 0
B34: Strength | C34: =('+Strength'!$P$15-Baseline!$P$15)/10 -> 33.075504 | D34: =C34/MAX($C$33:$C$42) -> 0.2034276
B35: Stamina | C35: =('+Stamina'!$P$15-Baseline!$P$15)/10 -> 0 | D35: =C35/MAX($C$33:$C$42) -> 0
B36: Critical Strike | C36: =('+Critical Strike'!$P$15-Baseline!$P$15)/10 -> 21.203397 | D36: =C36/MAX($C$33:$C$42) -> 0.13040939
B37: Haste | C37: =('+Haste'!$P$15-Baseline!$P$15)/10 -> 25.269648 | D37: =C37/MAX($C$33:$C$42) -> 0.15541846
B38: Versatility | C38: =('+Versatility'!$P$15-Baseline!$P$15)/10 -> 16.403834 | D38: =C38/MAX($C$33:$C$42) -> 0.10089016
B39: Mastery | C39: =('+Mastery'!$P$15-Baseline!$P$15)/10 -> 20.442419 | D39: =C39/MAX($C$33:$C$42) -> 0.12572907
B40: Leech | C40: =('+Leech'!$P$15-Baseline!$P$15)/10 -> 0 | D40: =C40/MAX($C$33:$C$42) -> 0
B41: Avoidance | C41: =('+Avoidance'!$P$15-Baseline!$P$15)/10 -> 0 | D41: =C41/MAX($C$33:$C$42) -> 0
B42: Weapon DPS | C42: ='+Weapon DPS'!$P$15-Baseline!$P$15 -> 162.59103 | D42: =C42/MAX($C$33:$C$42) -> 1
B43: Pawn String | C43: ="( Pawn: v1: ""BDK Priority DPS"": Leech="&D40&", CritRating="&D36&", Dps="&D42&", Strength="&D34&", HasteRating="&D37&", MasteryRating="&D39&", Stamina="&D35&", Armor="&D33&", Versatility="&D38&" )" -> ( Pawn: v1: "BDK Priority DPS": Leech=0, CritRating=0.13040939201827, Dps=1, Strength=0.203427604503727, HasteRating=0.155418463575789, MasteryRating=0.125729070391337, Stamina=0, Armor=0, Versatility=0.100890155742055 )
B45: Reliable EHP Stat Weights | C45: Raw | D45: Normalized
B46: Armor | C46: =('+Armor'!$Q$15-Baseline!$Q$15)/10 -> 794.25298 | D46: =C46/MAX($C$46:$C$55) -> 0.66532821
...

Sheet Baseline
B2: Baseline Profile
B4: Input Attributes | C4: Character Sheet | D4: Averate Ratings | E4: Diminished Ratings | G4: Attribute Calculations | N4: Damage Taken Breakdown
B5: Armor | C5: =Inputs!C7 -> 3852 | G5: Base Armor | H5: =C5/(1+C21*0.05*(1+0.2*C63)) -> 3852 | I5: Modified Armor | J5: =(C5*1.45+((J6*(1+E116)*(1+D157)*1.8)+IF(E28=3,1,0)*1.13*(1-exp(-1*$J$9*12/60))*($J$6*(1+E116)*(1+D157)*0.02*$J$10)))*(1+0.06*C75) -> 12077.944 | K5: Physical Damage Reduction | L5: =(J5 / (J5 + C154)) -> 0.75277812 | N5: Damage Taken Per Second | O5: Unmitigated | P5: Passively Mitigated | Q5: Dancing Rune Weapon Mitigation | R5: Icebound Fortitude Mitigated | S5: Misc Mitigation | T5: Fully Mitigated | U5: Anti-Magic Zone Healing | V5: Anti-Magic Shell Healing | W5: Other Healing | X5: EHRPS
B6: Strength | C6: =Inputs!C8 -> 2672 | G6: Base Strength | H6: =C6/(1+C21*0.05*(1+0.2*C63))-C34*33 -> 2672 | I6: Modified Strength | J6: =(C6+E32*252*8/120+E34*50)*(1+B21*1.13*(1-exp(-3*J9*15/60))*0.15*(1+0.2*C63))*(1+0.03*C77*(1-(0.85)^(8*L9)))*(1+0.1*12*(1/S40)*C131*(1-IF(OR(D100=1,AND(C152<4,C131=1)),0,1)*IF(D100=2,1-(1-(0.75)^((5+(H15/2))/H15))/(1+3*(1-(0.75)^((5+(H15/2))/H15))*C82),1)*IF(NOT(OR(OR(D100=1,AND(C152<4,C131=1)),D100=2)),1-(1-(0.75)^((4+(H15/2))/H15)),1)))*(1+0.1*T69*8*IF(C152=1,1,0)) -> 2890.6542 | K6: Raw Parry from Strength | L6: =(J6-622)/19130 -> 0.11859144 | N6: Physical ST Damage | O6: =P6/(1-$L$14)/(1-$L$5)/$L$10/(1-0.01*E32)/(1-0.2/C152*C74)/(1-C51*0.12/C152*1.13*(1-exp(-3*6/60*55/120)))/(1-$C$135*$C$130*$D$130*0.075)/(1-$C$131*E136*10/S40*0.08)/(1-F116)/(1-E157)/(1-IF(C127>1,1)*0.06*E127)/(1-(0.04*10*(1/S40)*C100*(1-IF(OR(D100=1,AND(C152<4,C131=1)),0,1)*IF(D100=2,1-(1-(0.75)^((5+(H15/2))/H15))/(1+3*(1-(0.75)^((5+(H15/2))/H15))*C82),1)*IF(NOT(OR(OR(D100=1,AND(C152<4,C131=1)),D100=2)),1-(1-(0.75)^((4+(H15/2))/H15)),1))))/(1-C120*0.025)+E26*C152/2*C7*0.0003*30 -> 3608042.3 | P6: =Q6/(1-((1-(1-(T38*(8+C110*4)))*(1-IF(C127>3,1,0)*(1-0.875^(8*(T40+T43+T51+T57+T63)))))*MIN(0.3/(1-$L$14),1))) -> 428388.04 | Q6: =R6/(1-($T$52*8)*(0.3+0.1*$E$139)) -> 328767.12 | R6: =S6/(1-($T$70*8)*0.1)/(1-($T$26*8)*0.1)/(1-($T$35*($Q$35+8/2^($D$121-1)))*(0.05*$D$121)) -> 320000 | S6: =T6 -> 320000 | T6: =(1-C146-C147)*T10 -> 320000
B7: Stamina | C7: =Inputs!C9 -> 77197 | G7: Base Stamina | H7: =(C7/(1+C21*0.05*(1+0.2*C63))/1.05/(1+0.2*C55)/(1.4))-C26*99 -> 43762.472 | I7: Total Health | J7: =C7*20 -> 1543940 | K7: Modified Health | L7: =(J7+IF(E28=3,1,0)*1.13*(1-exp(-1*$J$9*12/60))*($J$6*1.3*$J$10))*(1+0.01*C97*(D97+2*C104)) -> 1682894.6 | N7: Physical AoE Damage | O7: =P7/$J$13/(1-$L$5)/$L$10/(1-0.01*E32)/(1-C51*0.12/C152*1.13*(1-exp(-3*6/60*55/120)))/(1-$C$135*$C$130*$D$130*0.075)/(1-$C$131*E136*10/S40*0.08)/(1-IF(C127>1,1)*0.06*E127)/(1-(0.04*10*(1/S40)*C100*(1-IF(OR(D100=1,AND(C152<4,C131=1)),0,1)*IF(D100=2,1-(1-(0.75)^((5+(H15/2))/H15))/(1+3*(1-(0.75)^((5+(H15/2))/H15))*C82),1)*IF(NOT(OR(OR(D100=1,AND(C152<4,C131=1)),D100=2)),1-(1-(0.75)^((4+(H15/2))/H15)),1))))/(1-C120*0.025) -> 0 | P7: =R7/(1-($T$52*8)*(0.3+0.1*$E$139)) -> 0 | R7: =S7/(1-($T$70*8)*0.1)/(1-($T$26*8)*0.1)/(1-($T$35*($Q$35+8/2^($D$121-1)))*(0.05*$D$121)) -> 0 | S7: =T7 -> 0 | T7: =C147*T10 -> 0
B8: Critical Strike Rating | C8: =Inputs!C10 -> 778.5 | D8: =C8+225*15/2/120*IF(1<(IF(C8>C9,1,0)+IF(C8>C10,1,0)+IF(C8>C11,1,0)),E27,0) -> 778.5 | E8: =IF(D8<=1380,D8,IF(D8<=1840,1380+0.9*(D8-1380),IF(D8<=2300,1794+0.8*(D8-1840),IF(D8<=2760,2162+0.7*(D8-2300),IF(D8<=3680,2484+0.6*(D8-2760),IF(D8<=9200,3036+0.5*(D8-3680),5796)))))) -> 778.5 | G8: Critical Strike | H8: =E8/4600+0.05+(C28+C32+C35)*0.01+IF(E28=4,1,0)*1.13*(1-exp(-1*$J$9*12/60))*0.04 -> 0.21923913 | I8: Critical Strike Multiplier | J8: =1+H8*(1+2*0.02*(C26+C31)) -> 1.2192391 | K8: Raw Parry from Critical Strike | L8: =E8/5200/(1+0.02*C30) -> 0.14971154 | N8: Magical ST Damage | O8: =P8/$L$10/(1-C51*0.12/C152*1.13*(1-exp(-3*6/60*55/120)))/(1-$C$135*$C$130*$D$130*0.075)/(1-0.08*$C$80)/(1-IF(C127>1,1)*0.06*E127)/(1-(0.04*10*(1/S40)*C100*(1-IF(OR(D100=1,AND(C152<4,C131=1)),0,1)*IF(D100=2,1-(1-(0.75)^((5+(H15/2))/H15))/(1+3*(1-(0.75)^((5+(H15/2))/H15))*C82),1)*IF(NOT(OR(OR(D100=1,AND(C152<4,C131=1)),D100=2)),1-(1-(0.75)^((4+(H15/2))/H15)),1))))/(1-C120*0.025) -> 112528.84 | P8: =R8/(1-($T$52*8)*(0.3+0.1*$E$139)) -> 82191.781 | R8: =S8/(1-($T$70*8)*0.1)/(1-($T$26*8)*0.1)/(1-($T$35*($Q$35+8/2^($D$121-1)))*(0.05*$D$121)) -> 80000 | S8: =T8 -> 80000 | T8: =(C146-C148)*T10 -> 80000 | U8: =T8*(T20*(6+2*C67))*0.15 -> 0 | V8: =IF(T8-U8-$T$19*(($L$7*0.3*$J$10*(1+0.4*$C$68)*(1+0.15*$C$46)))>0,$T$19*($L$7*0.3*$J$10*(1+0.4*$C$68)*(1+0.15*$C$46)),T8-U8) -> 11765.668
B9: Haste Rating | C9: =Inputs!C11 -> 1053.5 | D9: =C9+225*15/2/120*IF(1<(IF(C9>C8,1,0)+IF(C9>C10,1,0)+IF(C9>C11,1,0)),E27,0) -> 1053.5 | E9: =IF(D9<=1320,D9,IF(D9<=1760,1320+0.9*(D9-1320),IF(D9<=2200,1716+0.8*(D9-1760),IF(D9<=2640,2068+0.7*(D9-2200),IF(D9<=3520,2376+0.6*(D9-2640),IF(D9<=8800,2904+0.5*(D9-3520),5544)))))) -> 1053.5 | G9: Haste | H9: =(1+(C29+C33)*0.01)*E9/4400+(C29+C33)*0.01 -> 0.23943182 | I9: Haste Multiplier | J9: =(1+H9)*(1+C27*0.15/18)*(1+0.1*C104)*(1+0.02*C49)*(1+0.01*K134) -> 1.5245749 | K9: Rune Regeneration | L9: =3/10*J9 -> 0.45737248 | N9: Magical AoE Damage | O9: =P9/$J$13/$L$10/(1-C51*0.12/C152*1.13*(1-exp(-3*6/60*55/120)))/(1-$C$135*$C$130*$D$130*0.075)/(1-0.08*$C$80)/(1-IF(C127>1,1)*0.06*E127)/(1-(0.04*10*(1/S40)*C100*(1-IF(OR(D100=1,AND(C152<4,C131=1)),0,1)*IF(D100=2,1-(1-(0.75)^((5+(H15/2))/H15))/(1+3*(1-(0.75)^((5+(H15/2))/H15))*C82),1)*IF(NOT(OR(OR(D100=1,AND(C152<4,C131=1)),D100=2)),1-(1-(0.75)^((4+(H15/2))/H15)),1))))/(1-C120*0.025) -> 0 | P9: =S9/(1-($T$52*8)*(0.3+0.1*$E$139)) -> 0 | R9: =S9/(1-($T$70*8)*0.1)/(1-($T$26*8)*0.1)/(1-($T$35*($Q$35+8/2^($D$121-1)))*(0.05*$D$121)) -> 0 | S9: =T9 -> 0 | T9: =C148*T10 -> 0 | U9: =T8*(T20*(6+2*C67))*0.15 -> 0 | V9: =IF(T8+T9-U8-U9-V8>0,MIN($T$19*($L$7*0.3*$J$10*(1+0.4*$C$68)*(1+0.15*$C$46))-V8,T8+T9-U8-U9-V8),0) -> 0
B10: Versatility Rating | C10: =Inputs!C12 -> 1514.5 | D10: =C10+65*E24+225*15/2/120*IF(1<(IF(C10>C8,1,0)+IF(C10>C9,0)+IF(C10>C11,1,0)),E27,0) -> 1514.5 | E10: =IF(D10<=1620,D10,IF(D10<=2160,1622+0.9*(D10-1620),IF(D10<=2700,2106+0.8*(D10-2160),IF(D10<=3240,2538+0.7*(D10-2700),IF(D10<=4320,2916+0.6*(D10-3240),IF(D10<=10800,3564+0.5*(D10-4320),6804)))))) -> 1514.5 | G10: Versatility | H10: =E10/5400+(E26+E33)*0.01 -> 0.28046296 | I10: Damage/Healing Multiplier | J10: =1+H10 -> 1.280463 | K10: Damage Taken Multiplier | L10: =1-H10/2 -> 0.85976852 | N10: Total | O10: =SUM(O6:O9) -> 3720571.1 | P10: =SUM(P6:P9) -> 510579.82 | Q10: =SUM(Q6:Q9) -> 328767.12 | R10: =SUM(R6:R9) -> 400000 | S10: =SUM(S6:S9) -> 400000 | T10: =C145 -> 400000 | U10: =SUM(U6:U9) -> 0 | V10: =sum(V6:V9) -> 11765.668 | W10: =(Y77+C27*0.0011*L7*(1-C144)) -> 384443.55 | X10: =(MAX((T10-U10-V10-W10),0)*(1-$T$76*(10+2*C92))+MAX((T10-U10-V10-W10*(1.3+0.05*C92)),0)*($T$76*(10+2*C92))/(1.3+0.05*C92))/IF(D100=2,(1+0.06*(1-T40*(1-(0.75)^((5+(H15/2))/H15))/(1+3*(1-(0.75)^((5+(H15/2))/H15))*C82)/(1-(0.75)^((5+(H15/2))/H15)))),(1+0.02*C49)) -> 1257.4746
B11: Mastery Rating | C11: =Inputs!C13 -> 479.5 | D11: =C11+225*15/2/120*IF(1<(IF(C11>C8,1,0)+IF(C11>C10,1,0)+IF(C11>C9,1,0)),E27,0) -> 479.5 | E11: =IF(D11<=1380,D11,IF(D11<=1840,1380+0.9*(D11-1380),IF(D11<=2300,1794+0.8*(D11-1840),IF(D11<=2760,2162+0.7*(D11-2300),IF(D11<=3680,2484+0.6*(D11-2760),IF(D11<=9200,3036+0.5*(D11-3680),5796)))))) -> 479.5 | G11: Mastery | H11: =0.16+E11/2300+0.002*(C131*K134) -> 0.38352364 | I11: Blood Shield Multiplier | J11: =H11 -> 0.38352364 | K11: Attack Power Multiplier | L11: =1+H11/2 -> 1.1917618
B12: Leech Rating | C12: =Inputs!C14 -> 0 | D12: =C12 -> 0 | E12: =IF(D12<=690,D12,IF(D12<=1035,690+0.8*(D12-690),IF(D12<=1380,966+0.6*(D12-1035),1173+0.4*(D12-1380)))) -> 0 | G12: Leech | H12: =E12/6900+C71*0.03+C131*E138*0.02 -> 0.03 | I12: Leech Healing Multiplier | J12: =H12 -> 0.03 | K12: Modified Leech Multiplier | L12: =J12+C111*0.15*MIN(8*T42,1)+0.06*(10+2*$C$72)*T54*(1+C131*E138) -> 0.185
B13: Avoidance Rating | C13: =Inputs!C15 -> 0 | D13: =C13 -> 0 | E13: =IF(D13<=368,D13,IF(D13<=552,368+0.8*(D13-368),IF(D13<=736,515.2+0.6*(D13-552),625.6+0.4*(D13-736)))) -> 0 | G13: Avoidance | H13: =E13/3680+C70*0.03 -> 0 | I13: AoE Damage Taken Multiplier | J13: =1-H13 -> 1 | K13: Total Parry Chance | L13: =622/19130+0.03+(L6+L8)/((L6+L8)*1+1/0.94)+0.05*8*T28 -> 0.26392296 | N13: Performance Measures
B14: Base Weapon DPS | C14: =Inputs!C16 -> 151.4 | G14: Dodge | H14: =0.03+0.02*C32 -> 0.03 | I14: Misc. Damage Done Multiplier | J14: =(1+E30*0.05*(1.13*(1-exp(-1*J9*15/60))))*(1+C57*0.06*(1-0.85^(5/(3/((1/(1-0.15*C107))*(1+C130))))))*(1+C117*0.05)*IF(D100=2,(1+0.06*C119*(1-T40*(1-(0.75)^((5+(H15/2))/H15))/(1+3*(1-(0.75)^((5+(H15/2))/H15))*C82)/(1-(0.75)^((5+(H15/2))/H15)))),(1+0.06*(14-5*C131*E137)*C119*(1/S40)))*(1+IF(C127>2,2,IF(C127=2,1,0))*0.03*E127) -> 1.1873319 | K14: Attack Avoidance Chance | L14: =MAX(L13-0.015*(C153-90),0)+MAX(H14-0.015*(C153-90),0)+MAX(0.03-0.015*(C153-90),0) -> 0.32392296 | N14: Mitigation Factor | O14: Overall DPS | P14: Priority DPS | Q14: Reliable EHP | R14: Reliable and Controllable EHP | S14: Unreliable EHP
B15: Base Weapon Speed | C15: =Inputs!C17 -> 3.6 | G15: Ave. Weapon Speed | H15: =C15/(J9*(1+0.06*(3+1.5*C130*C136)*C59*D59))/((195.5+21.9*C152-0.673*C152^2)/195.5) -> 1.3785993 | I15: Misc. Healing Done Multiplier | J15: =(1+E30*0.05*(1.13*(1-exp(-1*J9*15/60))))*IF(D100=2,(1+0.06*C119*(1-T40*(1-(0.75)^((5+(H15/2))/H15))/(1+3*(1-(0.75)^((5+(H15/2))/H15))*C82)/(1-(0.75)^((5+(H15/2))/H15)))),(1+0.02*C49))*(1+C73*0.15*(5+2*C68)*(1/S19*C149*(1-C150)))*(1+0.01*E31) -> 1.04 | K15: Bone Shield Consumption | L15: =IF(C127=4,1/(2.5+(2/(1-(L14+0.3*(0.151+0.367*(J8)-0.0791*(J8)^2+0.0086*(J8)^3)))-1+IF(C152=1,0.5,0))/C152),1/(2.5+(2/(1-(L14+0.3*T38*(8+C110*4)))-1+IF(C152=1,0.5,0))/C152)) -> 0.32692409 | N15: =IF(X10=0,"Self-Sufficient (+"&Round(-((T10-U10-V10-W10)*(1-$T$76*(10+2*C92))+(T10-U10-V10-W10*(1.3+0.05*C92))*($T$76*(10+2*C92)))/O10%,2)&"%)",($O$10-$X$10)/$O$10) -> 0.99966202 | O15: =V77 -> 324430.93 | P15: =W77 -> 112067.47 | Q15: =$L$7/(1-(1-(1-$L$5)*(1-$C$131*E136*10/S40*0.08))*(($T$6/(1-$L$14)/(1-((1-(1-(T38*(8+C110*4)))*(1-IF(C127>3,1,0)*8*0.125*(T40+T43+T51+T57+T63)))*MIN(0.3/(1-$L$14),1)))+$T$7)/(1-$L$5))/((($T$6/(1-$L$14)/(1-((1-(1-(T38*(8+C110*4)))*(1-IF(C127>3,1,0)*8*0.125*(T40+T43+T51+T57+T63)))*MIN(0.3/(1-$L$14),1)))+$T$7)/(1-$L$5))+$T$8+$T$9))/$L$10*(0.7+0.3/(1-0.15*C79-0.05*IF(C79>0,1,0)))/(1-$C$135*$C$130*$D$130*0.075)/(1-(0.08*$C$80)*(1-(($T$6/(1-$L$14)/(1-((1-(1-(T38*(8+C110*4)))*(1-IF(C127>3,1,0)*8*0.125*(T40+T43+T51+T57+T63)))*MIN(0.3/(1-$L$14),1)))+$T$7)/(1-$L$5))/((($T$6/(1-$L$14)/(1-((1-(1-(T38*(8+C110*4)))*(1-IF(C127>3,1,0)*8*0.125*(T40+T43+T51+T57+T63)))*MIN(0.3/(1-$L$14),1)))+$T$7)/(1-$L$5))+$T$8+$T$9)))/(1-(0.05*C131*E136)*((($T$6/(1-$L$14)/(1-((1-(1-(T38*(8+C110*4)))*(1-IF(C127>3,1,0)*8*0.125*(T40+T43+T51+T57+T63)))*MIN(0.3/(1-$L$14),1)))+$T$7)/(1-$L$5))/((($T$6/(1-$L$14)/(1-((1-(1-(T38*(8+C110*4)))*(1-IF(C127>3,1,0)*8*0.125*(T40+T43+T51+T57+T63)))*MIN(0.3/(1-$L$14),1)))+$T$7)/(1-$L$5))+$T$8+$T$9))) -> 9369364.5 | R15: =$L$7/(1-(1-(1-$L$5)*(1-$C$131*E136*10/S40*0.08))*(($T$6/(1-$L$14)/(1-((1-(1-(T38*(8+C110*4)))*(1-IF(C127>3,1,0)*8*0.125*(T40+T43+T51+T57+T63)))*MIN(0.3/(1-$L$14),1)))+$T$7)/(1-$L$5))/((($T$6/(1-$L$14)/(1-((1-(1-(T38*(8+C110*4)))*(1-IF(C127>3,1,0)*8*0.125*(T40+T43+T51+T57+T63)))*MIN(0.3/(1-$L$14),1)))+$T$7)/(1-$L$5))+$T$8+$T$9))/$L$10*(0.7+0.3/(1-0.15*C79-0.05*IF(C79>0,1,0)))/(T10/(Q10+P7+P8+P9))*(1+$T$76*(10+2*C92)*0.3)/(1-$C$135*$C$130*$D$130*0.075)/(1-(0.08*$C$80)*(1-(($T$6/(1-$L$14)/(1-((1-(1-(T38*(8+C110*4)))*(1-IF(C127>3,1,0)*8*0.125*(T40+T43+T51+T57+T63)))*MIN(0.3/(1-$L$14),1)))+$T$7)/(1-$L$5))/((($T$6/(1-$L$14)/(1-((1-(1-(T38*(8+C110*4)))*(1-IF(C127>3,1,0)*8*0.125*(T40+T43+T51+T57+T63)))*MIN(0.3/(1-$L$14),1)))+$T$7)/(1-$L$5))+$T$8+$T$9)))/(1-(0.05*C131*E136)*((($T$6/(1-$L$14)/(1-((1-(1-(T38*(8+C110*4)))*(1-IF(C127>3,1,0)*8*0.125*(T40+T43+T51+T57+T63)))*MIN(0.3/(1-$L$14),1)))+$T$7)/(1-$L$5))/((($T$6/(1-$L$14)/(1-((1-(1-(T38*(8+C110*4)))*(1-IF(C127>3,1,0)*8*0.125*(T40+T43+T51+T57+T63)))*MIN(0.3/(1-$L$14),1)))+$T$7)/(1-$L$5))+$T$8+$T$9))) -> 11517617 | S15: =$L$7*O10/T10*(0.7+0.3/(1-0.15*C79-0.05*IF(C79>0,1,0)))*(1+($T$76*(10+2*C92))*0.3) -> 21754755
B17: Runeforging | G17: Abilities | H17: Attack Power Multiplier | I17: Specialization Multiplier | J17: Base/Tooltip Damage | K17: Overall Damage Per Cast | L17: Priority Damage Per Cast | M17: Average Healing Per Cast | N17: Runes Per Cast | O17: Runic Power Per Cast | P17: Bone Shield Per Cast | Q17: Cast Time | R17: Base Cooldown | S17: Effective Cooldown | T17: Casts Per Second | U17: Time Utilization | V17: Overall DPS | W17: Priority DPS | X17: HPS | Y17: EHPS | Z17: Runes Per Second | AA17: Runic Power Per Second | AB17: Bone Shield Per Second
B18: Razorice | C18: Sanguination | D18: Spellwarding | E18: Apocalypse | G18: Abomination Limb | Q18: =1.5/$J$9 -> 0.9838808 | R18: 120 | S18: =R18+$C$151 -> 120.8 | T18: =1/S18*C102*D102 -> 0 | U18: =T18*Q18 -> 0
B19: =Inputs!B21 | C19: =Inputs!C21 -> 1 | G19: Anti-Magic Shell | O19: =AA19/T19 -> 58.261065 | R19: 60 | S19: =(R19-20*C68+20*C81) -> 40 | T19: =1/S19*C149*C150 -> 0.01 | AA19: =T19*$J$10*(1+0.4*$C$68)*(1+0.15*$C$46)*25 -> 0.58261065
B20: Fallen Crusader | C20: Stoneskin Gargoyle | D20: Unending Thirst | G20: Anti-Magic Zone | Q20: =1.5/$J$9 -> 0.9838808 | R20: 240 | S20: =240-60*C67 -> 180 | T20: =1/S20*C61*D61 -> 0 | U20: =T20*Q20 -> 0
B21: =Inputs!B23 | C21: =Inputs!C23 | G21: Arcane Pulse | H21: 1.5 | J21: =($J$6*(1+$E$116)*(1+$D$157)+$C$14*6)*H21*$J$10*$L$11*(1+0.01*E25) -> 9466.3379 | K21: =J21*$J$8*$C$152*$J$14*(1+0.08*C120*D120) -> 70711.938 | L21: =K21/$C$152 -> 14142.388 | M21: =K21*$L$12 -> 13081.709 | Q21: =1.5/$J$9 -> 0.9838808 | R21: 180 | S21: =R21+$C$151 -> 180.8 | T21: =1/S21*E25 -> 0 | U21: =T21*Q21 -> 0 | V21: =T21*K21 -> 0 | W21: =T21*L21 -> 0 | X21: =T21*M21 -> 0 | Y21: =X21*(1-$C$144) -> 0
G22: Arcane Torrent | O22: =20 -> 20 | Q22: =1.5/$J$9 -> 0.9838808 | R22: 120 | S22: =R22+$C$151 -> 120.8 | T22: =1/S22*C28 -> 0 | U22: =T22*Q22 -> 0 | AA22: =T22*O22 -> 0
B23: Race | G23: Auto-Attack | H23: =5*C15/12*1.25*1.2 -> 2.25 | J23: =($J$6*(1+$E$116)*(1+$D$157)+169*15/120*$C$24+$C$14*6)*H23*$J$10*$L$11 -> 14199.507 | K23: =J23*$J$8*0.7*$J$14*(1+0.08*C120*D120) -> 14849.507 | L23: =K23 -> 14849.507 | M23: =K23*$L$12 -> 2747.1588 | R23: =C15 -> 3.6 | S23: =H15 -> 1.3785993 | T23: =1/S23 -> 0.72537393 | V23: =T23*K23 -> 10771.445 | W23: =T23*L23 -> 10771.445 | X23: =T23*M23 -> 1992.7174 | Y23: =X23*(1-$C$144) -> 1594.1739
B24: Orc | C24: =Inputs!C26 -> 0 | D24: Pandaren | E24: =Inputs!E26 -> 0 | G24: Blood Beasts | H24: =0.1115*1.4/6*1.36*1.075*15 -> 0.5705455 | I24: 1.15 | J24: =($J$6*(1+$E$116)*(1+$D$157)+169*15/120*$C$24+$C$14*6)*H24*$J$10*$L$11*I24*(1+0.01*C24) -> 4140.7486 | K24: =(J24*$J$8*INT($J$9*10/1+1)*0.7*$J$14+J24*7.875*1.25*$J$8*$C$152/SQRT(MAX(1,$C$152/8))*$J$14)*(1+0.15*$C$152/SQRT(MAX(1,$C$152/8))*(1+$C$131*0.05*MIN(1,5/$C$152))*J10) -> 727368.01 | L24: =(J24*$J$8*INT($J$9*10/1+1)*0.7*$J$14+J24*7.875*1.25*$J$8/SQRT(MAX(1,$C$152/8))*$J$14)+(K24/(1+0.15*$C$152/SQRT(MAX(1,$C$152/8))*(1+$C$131*0.05*MIN(1,5/$C$152))*J10))*(0.15*1/SQRT(MAX(1,$C$152/8))*(1+$C$131*0.05)*J10) -> 199182.71 | M24: =K24/((1+$C$131*0.05*MIN(1,5/$C$152)))/$C$152 -> 138546.29 | S24: =S38 -> 90.8 | T24: =1/S24*C131 -> 0.011013216 | V24: =T24*K24 -> 8010.6609 | W24: =T24*L24 -> 2193.6421 | X24: =T24*M24 -> 1525.8402 | Y24: =X24*(1-$C$144) -> 1220.6721
B25: Undead | C25: =Inputs!C27 -> 0 | D25: Nightborne | E25: =Inputs!E27 -> 0 | G25: Blood Boil | H25: =1.4256*1.15 -> 1.63944 | I25: 1.15 | J25: =($J$6*(1+$E$116)*(1+$D$157)+169*15/120*$C$24+$C$14*6)*H25*$J$10*$L$11*I25*(1+0.01*$E$25)*(1+0.3*C130) -> 11898.278 | K25: =J25*$J$8*$C$152*$J$14*(1+C130*0.15*$B$19*(1+0.2*$C$63))*(1+$C$131*0.05*MIN(1,5/$C$152))*$H$135*(1+0.08*C120*D120) -> 93322.024 | L25: =K25/$C$152 -> 18664.405 | M25: =K25*$L$12 -> 17264.574 | Q25: =1.5/$J$9 -> 0.9838808 | R25: 7.5 | S25: =1/((1/(R25/J9))+(C113/((R25/J9)/((1/(1-0.15*C107))/3*(1+C130)*(1-(1-H8)^C152)*0.25)))) -> 4.919404 | T25: =MIN(1/S25,MAX((1-SUM(U19:U23,U29:U41,U43:U50,U52:U76)-($L$9+SUM(Z19:Z50,Z52:Z76))*Q51/(-N51)+(SUM(AA19:AA24,AA26:AA41,AA43:AA50,AA52:AA76)+(($L$9+SUM(Z19:Z50)+SUM(Z52:Z76))*O51/(-N51)))/O42*Q42)/Q25*(-O42/(O25-O42)),(1+C130)/24-T47*C130*0.5)) -> 0.041666667 | U25: =T25*Q25 -> 0.040995033 | V25: =(T25+C108*T51*(1-(1-0.15)*(1-0.15*MAX(4,C152-1)))*1.5)*K25 -> 40872.216 | W25: =(T25+C108*T51*(1-(1-0.15)*(1-0.15*MAX(4,C152-1)))*1.5)*L25 -> 8174.4432 | X25: =(T25+C108*T51*0.15*1.5)*M25 -> 2274.3579 | Y25: =X25*(1-$C$144) -> 1819.4863
B26: Tauren | C26: =Inputs!C28 -> 0 | D26: Highmountain | E26: =Inputs!E28 -> 0 | G26: Blood Draw | H26: 1.2 | I26: 1.15 | J26: =($J$6*(1+$E$116)*(1+$D$157)+169*15/120*$C$24+$C$14*6)*H26*$J$10*$L$11*I26*(1+0.01*$E$25) -> 8709.0308 | K26: =J26*$J$8*$C$152*$J$14*(1+$C$131*0.05*MIN(1,5/$C$152))*(1+0.08*C120*D120) -> 68307.732 | L26: =K26/$C$152 -> 13661.546 | M26: =K26*(1+$L$12)*1.25 -> 101180.83 | R26: 120 | S26: 120 | T26: =1/S26*C76 -> 0 | V26: =T26*K26 -> 0 | W26: =T26*L26 -> 0 | X26: =T26*M26 -> 0 | Y26: =X26*(1-$C$144) -> 0
B27: Troll | C27: =Inputs!C29 -> 0 | D27: Mag'har | E27: =Inputs!E29 -> 0 | G27: Blood Feast | M27: =V10/T19 -> 1176566.8 | T27: =T19*C112 -> 0 | X27: =T27*M27 -> 0 | Y27: =X27*(1-$C$144) -> 0
B28: Blood Elf | C28: =Inputs!C30 -> 0 | D28: Zandalari | E28: =Inputs!E30 -> 0 | G28: Blood Mist | H28: 0.64 | I28: 1.15 | J28: =($J$6*(1+$E$116)*(1+$D$157)+169*15/120*$C$24+$C$14*6)*H28*$J$10*$L$11*I28*(1+0.01*E25) -> 4644.8164 | K28: =J28*$J$8*$C$152/SQRT(MAX(1,$C$152/8))*$J$14*9*(1+0.08*C120*D120)*(1+$C$131*0.05*MIN(1,5/$C$152)) -> 327877.12 | L28: =K28/$C$152 -> 65575.423 | M28: =K28*$L$12 -> 60657.266 | O28: =MIN(C152,5)*2*9 -> 90 | T28: =T38*C118 -> 0 | V28: =T28*K28 -> 0 | W28: =T28*L28 -> 0 | X28: =T28*M28 -> 0 | Y28: =X28*(1-$C$144) -> 0 | AA28: =T28*O28 -> 0
B29: Goblin | C29: =Inputs!C31 -> 0 | D29: Vulpera | E29: =Inputs!E31 -> 0 | G29: Blood Plague | H29: =0.3348*24/3*(1/(1-0.15*C107)) -> 3.1510588 | I29: 1.15 | J29: =($J$6*(1+$E$116)*(1+$D$157)+169*15/120*$C$24+$C$14*6)*H29*$J$10*$L$11*I29*(1+0.01*E25) -> 22868.89 | K29: =J29*$J$8*$C$152*$J$14*(1+0.4*C117*D117)*(1+$C$131*0.05*MIN(1,5/$C$152))*(1+0.08*C120*D120)*(1+0.15*C131)/(1+0.05*C117) -> 259314.98 | L29: =K29/$C$152 -> 51862.996 | M29: =K29*(1+0.85*$C$107+$L$12)*1.25 -> 659632.48 | V29: =K29/24*(1+C130) -> 10804.791 | W29: =L29/24*(1+C130) -> 2160.9582 | X29: =M29/24*(1+C130) -> 27484.687 | Y29: =X29*(1-$C$144) -> 21987.749
B30: Human | C30: =Inputs!C32 -> 0 | D30: Void Elf | E30: =Inputs!E32 -> 0 | G30: Blood Shield | M30: =MIN(J11*(MAX(5*0.2*T10*(1+0.05*C111),7/100*L7)*(1+0.15*C42))*$J$10*(1+0.15*C46)*(1+0.2*C115),(0.5+0.15*C114)*L7*MAX(1,T42/0.2)/(1+($T$76*(10+2*C92))*(0.3+0.05*C92))) -> 370024.84 | T30: =T42 -> 0.40134944 | X30: =MIN(T30,0.2)*M30 -> 74004.969 | Y30: =X30 -> 74004.969
B31: Dwarf | C31: =Inputs!C33 -> 0 | D31: Lightforged Draenei | E31: =Inputs!E33 -> 0 | G31: Bloody Demise | H31: 9 | J31: =($J$6*(1+$E$116)*(1+$D$157)+169*15/120*$C$24+$C$14*6)*H31*$J$10*$L$11*(1+0.01*E25) -> 56798.027 | K31: =J31*$J$8*(2*$C$152/3+1/3)*(1+$C$131*0.05*MIN(1,5.5/($C$152+0.5)))*$H$135 -> 266613.95 | L31: =K31/(2*$C$152/3+1/3) -> 72712.896 | M31: =K31*$L$12 -> 49323.581 | T31: =T42/10*C158 -> 0.040134944 | V31: =T31*K31 -> 10700.536 | W31: =T31*L31 -> 2918.328 | X31: =T31*M31 -> 1979.5992 | Y31: =X31 -> 1979.5992
B32: Night Elf | C32: =Inputs!C34 -> 0 | D32: Dark Iron Dwarf | E32: =Inputs!E34 -> 0 | G32: Bloodworms | H32: =0.235*1.4/6*1.075 -> 0.058945833 | I32: 1 | J32: =($J$6*(1+$E$116)*(1+$D$157)+169*15/120*$C$24+$C$14*6)*H32*$J$10*$L$11*I32*(1+0.01*C24) -> 372.00078 | K32: =J32*$J$8*INT($J$9*D101/1.4+1)*0.7*$J$14 -> 4146.6332 | L32: =K32 -> 4146.6332 | M32: =L7*0.5*0.15 -> 126217.1 | R32: =60/5 -> 12 | S32: =R32/1.13 -> 10.619469 | T32: =1/S32*C101 -> 0 | V32: =T32*K32 -> 0 | W32: =T32*L32 -> 0 | X32: =T32*M32 -> 0 | Y32: =X32 -> 0
B33: Gnome | C33: =Inputs!C35 -> 0 | D33: Kul Tiran | E33: =Inputs!E35 -> 0 | G33: Bloody Reflection | H33: 1.1 | I33: 1.15 | J33: =($J$6*(1+$E$116)*(1+$D$157)+169*15/120*$C$24+$C$14*6)*H33*$J$10*$L$11*I33*(1+0.01*$E$25) -> 7983.2783 | K33: =J33*$J$8*$J$14*(1+$C$131*0.05*MIN(1,5/$C$152))*$H$135*(1+0.08*C127) -> 16017.898 | L33: =K33/C$152 -> 3203.5797 | M33: =K33*$L$12 -> 2963.3112 | R33: 0.5 | S33: =1/T42 -> 2.4915944 | T33: =1/S33*C114 -> 0 | V33: =T33*K33 -> 0 | W33: =T33*L33 -> 0 | X33: =T33*M33 -> 0 | Y33: =X33 -> 0
B34: Draenei | C34: =Inputs!C36 -> 0 | D34: Mechagnome | E34: =Inputs!E36 -> 0 | G34: Brush it Off | X34: =T10*0.02*E33 -> 0 | Y34: =X34*(1-$C$144) -> 0
B35: Worgen | C35: =Inputs!C37 -> 0 | E35: =Inputs!E37 | F35: =H35/H25 -> 3.8128385 | G35: Consumption | H35: =4.8084*1.3 -> 6.25092 | I35: 1.15 | J35: =($J$6*(1+$E$116)*(1+$D$157)+169*15/120*$C$24+$C$14*6)*H35*$J$10*$L$11*I35*(1+0.01*$E$25) -> 45366.213 | K35: =J35*$J$8*$C$152/SQRT(MAX(1,$C$152/8))*$J$14*(1+$C$131*0.05*MIN(1,5/$C$152))*(1+0.08*C120*D120)+24/(1+C130)*V29*D121*0.25*(1+0.08*C120*D120) -> 422725.07 | L35: =K35/$C$152 -> 84545.015 | M35: =K35*$L$12+24/(1+C130)*V29*D121*0.25*(1+0.08*C120*D120)*(1+0.5*$C$107+$L$12)*1.25+K35*C125*1.5*J11*J10*(1+0.15*C46)*(1+0.2*C115)/(1-$C$144) -> 219119.14 | Q35: =(1+0.5*D121)/$J$9 -> 0.9838808 | R35: 45 | S35: =(R35/(1+$C$125*22.5*1.1/60*1.13*$J$9))+$C$151 -> 45.8 | T35: =1/S35*C121 -> 0 | U35: =T35*Q35 -> 0 | V35: =T35*K35 -> 0 | W35: =T35*L35 -> 0 | X35: =T35*M35 -> 0 | Y35: =X35*(1-$C$144) -> 0
G36: Corrosive Vial | H36: 2.52 | J36: =($J$6*(1+$E$116)*(1+$D$157)+$C$14*6)*H36*$J$10*$L$11 -> 15903.448 | K36: =J36*$J$8*$J$14*(1+0.08*C120*D120) -> 23759.211 | L36: =K36 -> 23759.211 | Q36: =1.5/$J$9 -> 0.9838808 | R36: 90 | S36: =R36+$C$151 -> 90.8 | T36: =1/S36*IF($E$29=1,1,0) -> 0 | U36: =T36*Q36 -> 0 | V36: =T36*K36 -> 0 | W36: =T36*L36 -> 0 | X36: =T36*M36 -> 0 | Y36: =X36*(1-$C$144) -> 0
B37: Death Knight Talents | C37: Rank | D37: Variable | G37: Dance of Midnight (Runes) | N37: 1 | T37: =F127 -> 0.14029744 | Z37: =T37*N37 -> 0.14029744
A38: Row 1 | B38: Icebound Fortitude | C38: =Inputs!C40 -> 1 | G38: Dancing Rune Weapon | I38: 1 | K38: =(SUM(V25,V42*(1+0.08*C120*D120)/(1+0.08*C120)/(1+0.6*C19*(1+0.2*C63))*MAX(1,MIN(1+C106*0.75*(C152-1),1+C106*1.5))/MAX((1+0.2*C63*C19),MIN((1+0.2*C63*C19)+C106*0.75*(C152-1),(1+0.2*C63*C19)+C106*1.5)),V43,IF(C131=1,0,V51),V57,IF(C131=1,V74*T51/T74,V74))*(8+4*C110)+INT((8+4*C110+H15/2)/H15)*V23+V29*(24/(1+C130)+(IF((8+4*C110)*T25-1>0,MIN((8+4*C110)*T25-1,1),0))*(8+4*C110)/2+(IF((8+4*C110)*T25-2>0,MIN((8+4*C110)*T25-2,1),0))*(8+4*C110)/6))*0.33*(1+0.01*$C$24)*(1+C110)*I38*(1+$C$131*0.05)*(1+C131*T51*8*0.2*(8+4*C110-4)/(8+4*C110))/(1+0.08*C120*D120)*(1+IF(C127>2,2,IF(C127=2,1,0))*0.03*E127) -> 2066007.8 | L38: =(SUM(W25,W42*(1+0.08*C120*D120)/(1+0.08*C120)/(1+0.6*C19*(1+0.2*C63))/(1+0.2*C63*C19),W43,IF(C131=1,0,W51),W57,IF(C131=1,W74*T51/T74,W74))*(8+4*C110)+INT((8+4*C110+H15/2)/H15)*W23+W29*(24/(1+C130)+(IF((8+4*C110)*T25-1>0,MIN((8+4*C110)*T25-1,1),0))*(8+4*C110)/2+(IF((8+4*C110)*T25-2>0,MIN((8+4*C110)*T25-2,1),0))*(8+4*C110)/6))*0.33*(1+0.01*$C$24)*(1+C110)*I38*(1+$C$131*0.05)*(1+C131*T51*8*0.2*(8+4*C110-4)/(8+4*C110))/(1+0.08*C120*D120)*(1+IF(C127>2,2,IF(C127=2,1,0))*0.03*E127) -> 641712.82 | P38: =D105*C105 -> 5 | Q38: =1.5/$J$9 -> 0.9838808 | R38: 120 | S38: =120-30*C105+$C$151 -> 90.8 | T38: =1/S38*C98*C149 -> 0.011013216 | U38: =T38*Q38 -> 0.010835692 | V38: =T38*K38 -> 22753.39 | W38: =T38*L38 -> 7067.3218 | AB38: =P38*T38 -> 0.055066079
B39: Death Strike | C39: =Inputs!C41 -> 1 | G39: Dancing Rune Weapon (DoM) | I39: 1 | K39: =(SUM(V25,V42*(1+0.08*C120*D120)/(1+0.08*C120)/(1+0.6*C19*(1+0.2*C63))*MAX(1,MIN(1+C106*0.75*(C152-1),1+C106*1.5))/MAX((1+0.2*C63*C19),MIN((1+0.2*C63*C19)+C106*0.75*(C152-1),(1+0.2*C63*C19)+C106*1.5)),V43,IF(C131=1,V51/(T51-T74)*(1-T38*(8+C110*4))*(T51-(0.35+0.05*14/S40*E136+E140*0.35*0.15)*T42),V51),V57,IF(C131=1,V74/T74*((1-T38*(8+C110*4))*((0.35+0.05*14/S40*E136+E140*0.35*0.15)*T42)+(T38*(8+C110*4))*T51),V74))*(6)+INT((6+H15/2)/H15)*V23+V29*(24/(1+C130)*(MIN(T25*6,1)+IF(T25*6>1,(T25*6-1)*3,0))))*0.33*(1+0.01*$C$24)*(1)*I38*(1+$C$131*0.05)*(1+C131*T51*8*0.2*(2)/(6))/(1+0.08*C120*D120)*(1+IF(C127>2,2,IF(C127=2,1,0))*0.03*E127) -> 452787.64 | L39: =(SUM(W25,W42*(1+0.08*C120*D120)/(1+0.08*C120)/(1+0.6*C19*(1+0.2*C63))/(1+0.2*C63*C19),W43,IF(C131=1,W51/(T51-T74)*(1-T38*(8+C110*4))*(T51-(0.35+0.05*14/S40*E136+E140*0.35*0.15)*T42),W51),W57,IF(C131=1,V74/T74*((1-T38*(8+C110*4))*((0.35+0.05*14/S40*E136+E140*0.35*0.15)*T42)+(T38*(8+C110*4))*T51),W74))*(6)+INT((6+H15/2)/H15)*W23+W29*(24/(1+C130)*(MIN(T25*6,1)+IF(T25*6>1,(T25*6-1)*3,0))))*0.33*(1+0.01*$C$24)*(1)*I38*(1+$C$131*0.05)*(1+C131*T51*8*0.2*(2)/(6))/(1+0.08*C120*D120)*(1+IF(C127>2,2,IF(C127=2,1,0))*0.03*E127) -> 179503.26 | S39: =IF(OR(D100=1,AND(C152<4,C131=1)),MAX((10-5*C131*E137+H15*3.5+C151),12),0)+IF(NOT(OR(D100=1,AND(C152<4,C131=1))),15-5*C131*E137-C82,0) -> 14 | T39: =IF(C127>3,1,0)*0.1*(T40+T43+T51+T57+T63) -> 0.056235397 | V39: =T39*K39 -> 25462.693 | W39: =T39*L39 -> 10094.437
B40: Raise Dead | C40: =Inputs!C42 -> 1 | G40: Death and Decay | H40: =0.083*(11+2*C107)*1.3*1.25 -> 1.753375 | I40: =1.48*1.15 -> 1.702 | J40: =($J$6*(1+$E$116)*(1+$D$157)+169*15/120*$C$24+$C$14*6)*H40*$J$10*$L$11*I40*(1+0.01*E25) -> 18833.243 | K40: =J40*$J$8*$C$152*$J$14*(1+$C$131*0.05*MIN(1,5/$C$152))*(1+0.08*C120*D120) -> 147715.19 | L40: =K40/$C$152 -> 29543.037 | M40: =K40*$L$12+($J$6*(1+$E$116)*(1+$D$157)+4925*15/120*C24+$C$14*6)*0.375*(D97+2*C104)*$J$10*$J$8*$L$11*C94*(1-IF(OR(D100=1,AND(C152<4,C131=1)),0,1)*IF(D100=2,1-(1-(0.75)^((5+(H15/2))/H15))/(1+3*(1-(0.75)^((5+(H15/2))/H15))*C82),1)*IF(NOT(OR(OR(D100=1,AND(C152<4,C131=1)),D100=2)),1-(1-(0.75)^((4+(H15/2))/H15)),1)) -> 43535.639 | N40: =-1*IF(OR(D100=1,AND(C152<4,C131=1)),0,1)*IF(D100=2,1-(1-(0.75)^((5+(H15/2))/H15))/(1+3*(1-(0.75)^((5+(H15/2))/H15))*C82),1)*IF(NOT(OR(OR(D100=1,AND(C152<4,C131=1)),D100=2)),1-(1-(0.75)^((4+(H15/2))/H15)),1) -> -0.37585594 | O40: =10*IF(OR(D100=1,AND(C152<4,C131=1)),C94,1)*IF(D100=2,IF(C94>0,1,1-(1-(0.75)^((5+(H15/2))/H15))/(1+3*(1-(0.75)^((5+(H15/2))/H15))*C82)),1)*IF(NOT(OR(OR(D100=1,AND(C152<4,C131=1)),D100=2)),IF(C94>0,1,1-(1-(0.75)^((4+(H15/2))/H15))),1) -> 10 | Q40: =1.5/$J$9 -> 0.9838808 | R40: 15 | S40: =IF(OR(D100=1,AND(C152<4,C131=1)),MAX((10-5*C131*E137+H15*3.5+C151),12),0)+IF(NOT(OR(D100=1,AND(C152<4,C131=1))),15-5*C131*E137-C82,0) -> 14 | T40: =1/S40 -> 0.071428571 | U40: =T40*Q40 -> 0.0702772 | V40: =T40*K40 -> 10551.085 | W40: =T40*L40 -> 2110.217 | X40: =T40*M40 -> 3109.6885 | Y40: =X40*(1-$C$144) -> 2487.7508 | Z40: =T40*N40 -> -0.026846853 | AA40: =T40*O40 -> 0.71428571
A41: Row 2 | B41: Runic Attenuation | C41: =Inputs!C43 -> 1 | G41: Death Pact | M41: =$L$7*(0.2+0.1*C62)*$J$10 -> 430976.84 | R41: 120 | S41: =R41-30*C62+$C$151 -> 120.8 | T41: =1/S41*C56 -> 0 | X41: =T41*M41 -> 0 | Y41: =X41 -> 0
B42: Improved Death Strike | C42: =Inputs!C44 -> 1 | G42: Death Strike | H42: =1.5312*1.2*1.12 -> 2.0579328 | I42: =2.3 -> 2.3 | J42: =($J$6*(1+$E$116)*(1+$D$157)+169*15/120*$C$24+$C$14*6)*H42*$J$10*$L$11*I42*(1+0.12*C130) -> 29871 | K42: =J42*$J$8*0.7*(1+C99*0.08*MIN((T25+C108*T51*(1-(1-0.15)*(1-0.15*MAX(4,C152-1))))/T42*C152,5))*(1+0.6*C19*(1+0.2*C63))*$J$14*(1+0.08*C120)*(1+0.05*K134)*MAX((1+0.2*C63*C19),MIN((1+0.2*C63*C19)+C106*0.75*(C152-1),(1+0.2*C63*C19)+C106*1.5)) -> 272610.76 | L42: =K42*(1+0.2*C63*C19)/MAX((1+0.2*C63*C19),MIN((1+0.2*C63*C19)+C106*0.75*(C152-1),(1+0.2*C63*C19)+C106*1.5)) -> 121160.34 | M42: =K42*$L$12+MAX(5*0.2*T10*(1+0.05*C111),7/100*L7)*(1+C99*0.08*MIN((T25+C108*T51*(1-(1-0.15)*(1-0.15*MAX(4,C152-1))))/T42*C152,5))*$J$10*$J$15*(1+0.15*C42) -> 889709.06 | O42: =(-45)+5*C91+IF(C42>0,5,0)+10*8*T26 -> -35 | Q42: =1.5/$J$9 -> 0.9838808 | T42: =-(SUM(AA19:AA41,AA43:AA76))/O42 -> 0.40134944 | U42: =T42*Q42 -> 0.39488 | V42: =T42*K42 -> 109412.18 | W42: =T42*L42 -> 48627.634 | X42: =MIN(T42,0.2)*M42 -> 177941.81 | Y42: =X42*(1-$C$144) -> 142353.45 | AA42: =T42*O42 -> -14.04723
B43: Cleaving Strikes | C43: =Inputs!C45 -> 1 | G43: Death's Caress | H43: =0.4374 -> 0.4374 | I43: 1.15 | J43: =($J$6*(1+$E$116)*(1+$D$157)+169*15/120*$C$24+$C$14*6)*H43*$J$10*$L$11*I43*(1+0.01*E25) -> 3174.4417 | K43: =J43*$J$8*$J$14*(1+$C$131*0.05)*(1+0.08*C120*D120) -> 4979.6337 | L43: =K43 -> 4979.6337 | M43: =K43*$L$12 -> 921.23223 | N43: -1 | O43: 10 | P43: 2 | Q43: =1.5/$J$9 -> 0.9838808 | R43: 6 | S43: =IF(4*Q43>=R43,4*Q43,(IF(5*Q43>=R43,5*Q43,(IF(6*Q43>=R43,6*Q43,(IF(7*Q43>=R43,7*Q43,(8*Q43)))))))) -> 6.8871656 | T43: =MIN(1/S43,(L15-SUM(AB19:AB42)-SUM(AB44:AB56)-SUM(AB61:AB76))/2)*D87 -> 0 | U43: =T43*Q43 -> 0 | V43: =T43*K43 -> 0 | W43: =T43*L43 -> 0 | X43: =T43*M43 -> 0 | Y43: =X43*(1-$C$144) -> 0 | Z43: =T43*N43 -> 0 | AA43: =T43*O43 -> 0 | AB43: =P43*T43 -> 0
...

Sheet Comparison
B2: Comparison Profile
B4: Input Attributes | C4: Character Sheet | D4: Averate Ratings | E4: Diminished Ratings | G4: Attribute Calculations | N4: Damage Taken Breakdown
B5: Armor | C5: =IF(ISBLANK(Inputs!H7),H5*(1+C21*0.05*(1+0.2*C63)),Inputs!H7) -> 3852 | G5: Base Armor | H5: =IF(ISBLANK(Inputs!H7),Baseline!H5+Inputs!I7,C5/(1+C21*0.05*(1+0.2*C63))) -> 3852 | I5: Modified Armor | J5: =(C5*1.45+((J6*(1+E116)*(1+D157)*1.8)+IF(E28=3,1,0)*1.13*(1-exp(-1*$J$9*12/60))*($J$6*(1+E116)*(1+D157)*0.02*$J$10)))*(1+0.06*C75) -> 12072.348 | K5: Physical Damage Reduction | L5: =(J5 / (J5 + C154)) -> 0.75269186 | N5: Damage Taken Per Second | O5: Unmitigated | P5: Passively Mitigated | Q5: Dancing Rune Weapon Mitigated | R5: Icebound Fortitude Mitigated | S5: Misc Mitigated | T5: Fully Mitigated | U5: Anti-Magic Zone Healing | V5: Anti-Magic Shell Healing | W5: Other Healing | X5: EHRPS
B6: Strength | C6: =IF(ISBLANK(Inputs!H8),(H6+C34*33)*(1+C21*0.05*(1+0.2*C63)),Inputs!H8) -> 2672 | G6: Base Strength | H6: =IF(ISBLANK(Inputs!H8),Baseline!H6+Inputs!I8,C6/(1+C21*0.05*(1+0.2*C63))) -> 2672 | I6: Modified Strength | J6: =(C6+E32*252*8/120+E34*50)*(1+B21*1.13*(1-exp(-3*J9*15/60))*0.15*(1+0.2*C63))*(1+0.03*C77*(1-(0.85)^(8*L9)))*(1+0.1*12*(1/S40)*C131*(1-IF(OR(D100=1,AND(C152<4,C131=1)),0,1)*IF(D100=2,1-(1-(0.75)^((5+(H15/2))/H15))/(1+3*(1-(0.75)^((5+(H15/2))/H15))*C82),1)*IF(NOT(OR(OR(D100=1,AND(C152<4,C131=1)),D100=2)),1-(1-(0.75)^((4+(H15/2))/H15)),1)))*(1+0.1*T69*8*IF(C152=1,1,0)) -> 2890.6542 | K6: Raw Parry from Strength | L6: =(J6-622)/19130 -> 0.11859144 | N6: Physical ST Damage | O6: =Baseline!O6 -> 3608042.3 | P6: =(O6-E26*C152/2*C7*0.0003*30)*(1-$L$14)*(1-$L$5)*$L$10*(1-0.01*E32)*(1-0.2/C152*C74)*(1-C51*0.12/C152*1.13*(1-exp(-3*6/60*55/120)))*(1-$C$135*$C$130*$D$130*0.075)*(1-$C$131*E136*10/S40*0.08)*(1-F116)*(1-E157)*(1-IF(C127>1,1)*0.06*E127)*(1-(0.04*10*(1/S40)*C100*(1-IF(OR(D100=1,AND(C152<4,C131=1)),0,1)*IF(D100=2,1-(1-(0.75)^((5+(H15/2))/H15))/(1+3*(1-(0.75)^((5+(H15/2))/H15))*C82),1)*IF(NOT(OR(OR(D100=1,AND(C152<4,C131=1)),D100=2)),1-(1-(0.75)^((4+(H15/2))/H15)),1))))*(1-C120*0.025) -> 428924.16 | Q6: =P6*(1-((1-(1-(T38*(8+C110*4)))*(1-IF(C127>3,1,0)*(1-0.875^(8*(T40+T43+T51+T57+T63)))))*MIN(0.3/(1-$L$14),1))) -> 330419.45 | R6: =Q6*(1-($T$52*8)*(0.3+0.1*$E$139)) -> 321608.27 | S6: =R6*(1-($T$70*8)*0.1)*(1-($T$26*8)*0.1)*(1-($T$35*($Q$35+8/2^($D$121-1)))*(0.05*$D$121)) -> 318454.02 | T6: =S6 -> 318454.02
B7: Stamina | C7: =IF(ISBLANK(Inputs!H9),(H7+C26*99)*(1+C21*0.05*(1+0.2*C63))*1.05*(1+0.2*C55)*(1.4),Inputs!H9) -> 77197 | G7: Base Stamina | H7: =IF(ISBLANK(Inputs!H9),Baseline!H7+Inputs!I9,(C7/(1+C21*0.05*(1+0.2*C63))/1.05/(1+0.2*C55)/(1.4))-C26*99) -> 43762.472 | I7: Total Health | J7: =C7*20 -> 1543940 | K7: Modified Health | L7: =(J7+IF(E28=3,1,0)*1.13*(1-exp(-1*$J$9*12/60))*($J$6*1.3*$J$10))*(1+0.01*C97*(D97+2*C104)) -> 1682894.6 | N7: Physical AoE Damage | O7: =Baseline!O7 -> 0 | P7: =O7*$J$13*(1-$L$5)*$L$10*(1-0.01*E32)*(1-C51*0.12/C152*1.13*(1-exp(-3*6/60*55/120)))*(1-$C$135*$C$130*$D$130*0.075)*(1-$C$131*E136*10/S40*0.08)*(1-IF(C127>1,1)*0.06*E127)*(1-(0.04*10*(1/S40)*C100*(1-IF(OR(D100=1,AND(C152<4,C131=1)),0,1)*IF(D100=2,1-(1-(0.75)^((5+(H15/2))/H15))/(1+3*(1-(0.75)^((5+(H15/2))/H15))*C82),1)*IF(NOT(OR(OR(D100=1,AND(C152<4,C131=1)),D100=2)),1-(1-(0.75)^((4+(H15/2))/H15)),1))))*(1-C120*0.025) -> 0 | R7: =P7*(1-($T$52*8)*(0.3+0.1*$E$139)) -> 0 | S7: =R7*(1-($T$70*8)*0.1)*(1-($T$26*8)*0.1)*(1-($T$35*($Q$35+8/2^($D$121-1)))*(0.05*$D$121)) -> 0 | T7: =S7 -> 0
B8: Critical Strike Rating | C8: =IF(ISBLANK(Inputs!H10),(Inputs!C10+Inputs!I10)*(1+0.02*$C$30)/(1+0.02*Baseline!$C$30),Inputs!H10) -> 778.5 | D8: =(C8+225*15/2/120*IF(1<(IF(C8>C9,1,0)+IF(C8>C10,1,0)+IF(C8>C11,1,0)),E27,0)) -> 778.5 | E8: =IF(D8<=1380,D8,IF(D8<=1840,1380+0.9*(D8-1380),IF(D8<=2300,1794+0.8*(D8-1840),IF(D8<=2760,2162+0.7*(D8-2300),IF(D8<=3680,2484+0.6*(D8-2760),IF(D8<=9200,3036+0.5*(D8-3680),5796)))))) -> 778.5 | G8: Critical Strike | H8: =E8/4600+0.05+(C28+C32+C35)*0.01+IF(E28=4,1,0)*1.13*(1-exp(-1*$J$9*12/60))*0.04 -> 0.21923913 | I8: Critical Strike Multiplier | J8: =1+H8*(1+2*0.02*(C26+C31)) -> 1.2192391 | K8: Raw Parry from Critical Strike | L8: =E8/5200/(1+0.02*C30) -> 0.14971154 | N8: Magical ST Damage | O8: =Baseline!O8 -> 112528.84 | P8: =O8*$L$10*(1-C51*0.12/C152*1.13*(1-exp(-3*6/60*55/120)))*(1-$C$135*$C$130*$D$130*0.075)*(1-0.08*$C$80)*(1-IF(C127>1,1)*0.06*E127)*(1-(0.04*10*(1/S40)*C100*(1-IF(OR(D100=1,AND(C152<4,C131=1)),0,1)*IF(D100=2,1-(1-(0.75)^((5+(H15/2))/H15))/(1+3*(1-(0.75)^((5+(H15/2))/H15))*C82),1)*IF(NOT(OR(OR(D100=1,AND(C152<4,C131=1)),D100=2)),1-(1-(0.75)^((4+(H15/2))/H15)),1))))*(1-C120*0.025) -> 82257.869 | R8: =P8*(1-($T$52*8)*(0.3+0.1*$E$139)) -> 80064.326 | S8: =R8*(1-($T$70*8)*0.1)*(1-($T$26*8)*0.1)*(1-($T$35*($Q$35+8/2^($D$121-1)))*(0.05*$D$121)) -> 79279.077 | T8: =S8 -> 79279.077 | U8: =T8*(T20*(6+2*C67))*0.15 -> 0 | V8: =IF(T8-U8-$T$19*(($L$7*0.3*$J$10*(1+0.4*$C$68)*(1+0.15*$C$46)))>0,$T$19*($L$7*0.3*$J$10*(1+0.4*$C$68)*(1+0.15*$C$46)),T8-U8) -> 11765.668
B9: Haste Rating | C9: =IF(ISBLANK(Inputs!H11),(Inputs!C11+Inputs!I11)*(1+0.02*$C$30)/(1+0.02*Baseline!$C$30),Inputs!H11) -> 1053.5 | D9: =(C9+225*15/2/120*IF(1<(IF(C9>C8,1,0)+IF(C9>C10,1,0)+IF(C9>C11,1,0)),E27,0)) -> 1053.5 | E9: =IF(D9<=1320,D9,IF(D9<=1760,1320+0.9*(D9-1320),IF(D9<=2200,1716+0.8*(D9-1760),IF(D9<=2640,2068+0.7*(D9-2200),IF(D9<=3520,2376+0.6*(D9-2640),IF(D9<=8800,2904+0.5*(D9-3520),5544)))))) -> 1053.5 | G9: Haste | H9: =(1+(C29+C33)*0.01)*E9/4400+(C29+C33)*0.01 -> 0.23943182 | I9: Haste Multiplier | J9: =(1+H9)*(1+C27*0.15/18)*(1+0.1*C104)*(1+0.02*C49)*(1+0.01*K134) -> 1.5245749 | K9: Rune Regeneration | L9: =3/10*J9 -> 0.45737248 | N9: Magical AoE Damage | O9: =Baseline!O9 -> 0 | P9: =O9*$J$13*$L$10*(1-C51*0.12/C152*1.13*(1-exp(-3*6/60*55/120)))*(1-$C$135*$C$130*$D$130*0.075)*(1-0.08*$C$80)*(1-IF(C127>1,1)*0.06*E127)*(1-(0.04*10*(1/S40)*C100*(1-IF(OR(D100=1,AND(C152<4,C131=1)),0,1)*IF(D100=2,1-(1-(0.75)^((5+(H15/2))/H15))/(1+3*(1-(0.75)^((5+(H15/2))/H15))*C82),1)*IF(NOT(OR(OR(D100=1,AND(C152<4,C131=1)),D100=2)),1-(1-(0.75)^((4+(H15/2))/H15)),1))))*(1-C120*0.025) -> 0 | R9: =P9*(1-($T$52*8)*(0.3+0.1*$E$139)) -> 0 | S9: =R9*(1-($T$70*8)*0.1)*(1-($T$26*8)*0.1)*(1-($T$35*($Q$35+8/2^($D$121-1)))*(0.05*$D$121)) -> 0 | T9: =S9 -> 0 | U9: =T8*(T20*(6+2*C67))*0.15 -> 0 | V9: =IF(T8+T9-U8-U9-V8>0,MIN($T$19*($L$7*0.3*$J$10*(1+0.4*$C$68)*(1+0.15*$C$46))-V8,T8+T9-U8-U9-V8),0) -> 0
B10: Versatility Rating | C10: =IF(ISBLANK(Inputs!H12),(Inputs!C12+Inputs!I12)*(1+0.02*$C$30)/(1+0.02*Baseline!$C$30),Inputs!H12) -> 1514.5 | D10: =(C10+65*E24+225*15/2/120*IF(1<(IF(C10>C8,1,0)+IF(C10>C9,0)+IF(C10>C11,1,0)),E27,0)) -> 1514.5 | E10: =IF(D10<=1620,D10,IF(D10<=2160,1622+0.9*(D10-1620),IF(D10<=2700,2106+0.8*(D10-2160),IF(D10<=3240,2538+0.7*(D10-2700),IF(D10<=4320,2916+0.6*(D10-3240),IF(D10<=10800,3564+0.5*(D10-4320),6804)))))) -> 1514.5 | G10: Versatility | H10: =E10/5400+(E26+E33)*0.01 -> 0.28046296 | I10: Damage/Healing Multiplier | J10: =1+H10 -> 1.280463 | K10: Damage Taken Multiplier | L10: =1-H10/2 -> 0.85976852 | N10: Total | O10: =SUM(O6:O9) -> 3720571.1 | P10: =SUM(P6:P9) -> 511182.03 | Q10: =SUM(Q6:Q9) -> 330419.45 | R10: =SUM(R6:R9) -> 401672.59 | S10: =SUM(S6:S9) -> 397733.1 | T10: =SUM(T6:T9) -> 397733.1 | U10: =SUM(U6:U9) -> 0 | V10: =sum(V6:V9) -> 11765.668 | W10: =(Y77+C27*0.0011*L7*(1-C144)) -> 383897.79 | X10: =(MAX((T10-U10-V10-W10),0)*(1-$T$76*(10+2*C92))+MAX((T10-U10-V10-W10*(1.3+0.05*C92)),0)*($T$76*(10+2*C92))/(1.3+0.05*C92))/IF(D100=2,(1+0.06*(1-T40*(1-(0.75)^((5+(H15/2))/H15))/(1+3*(1-(0.75)^((5+(H15/2))/H15))*C82)/(1-(0.75)^((5+(H15/2))/H15)))),(1+0.02*C49)) -> 709.06813
B11: Mastery Rating | C11: =IF(ISBLANK(Inputs!H13),(Inputs!C13+Inputs!I13)*(1+0.02*$C$30)/(1+0.02*Baseline!$C$30),Inputs!H13) -> 479.5 | D11: =(C11+225*15/2/120*IF(1<(IF(C11>C8,1,0)+IF(C11>C10,1,0)+IF(C11>C9,1,0)),E27,0)) -> 479.5 | E11: =IF(D11<=1380,D11,IF(D11<=1840,1380+0.9*(D11-1380),IF(D11<=2300,1794+0.8*(D11-1840),IF(D11<=2760,2162+0.7*(D11-2300),IF(D11<=3680,2484+0.6*(D11-2760),IF(D11<=9200,3036+0.5*(D11-3680),5796)))))) -> 479.5 | G11: Mastery | H11: =0.16+E11/2300+0.002*(C131*K134) -> 0.38352364 | I11: Blood Shield Multiplier | J11: =H11 -> 0.38352364 | K11: Attack Power Multiplier | L11: =1+H11/2 -> 1.1917618
B12: Leech Rating | C12: =IF(ISBLANK(Inputs!H14),Inputs!C14+Inputs!I14,Inputs!H14) -> 0 | D12: =C12 -> 0 | E12: =IF(D12<=690,D12,IF(D12<=1035,690+0.8*(D12-690),IF(D12<=1380,966+0.6*(D12-1035),1173+0.4*(D12-1380)))) -> 0 | G12: Leech | H12: =E12/6900+C71*0.03+C131*E138*0.02 -> 0.03 | I12: Leech Healing Multiplier | J12: =H12 -> 0.03 | K12: Modified Leech Multiplier | L12: =J12+C111*0.15*MIN(8*T42,1)+0.06*(10+2*$C$72)*T54*(1+C131*E138) -> 0.185
B13: Avoidance Rating | C13: =IF(ISBLANK(Inputs!H15),Inputs!C15+Inputs!I15,Inputs!H15) -> 0 | D13: =C13 -> 0 | E13: =IF(D13<=368,D13,IF(D13<=552,368+0.8*(D13-368),IF(D13<=736,515.2+0.6*(D13-552),625.6+0.4*(D13-736)))) -> 0 | G13: Avoidance | H13: =E13/3680+C70*0.03 -> 0 | I13: AoE Damage Taken Multiplier | J13: =1-H13 -> 1 | K13: Total Parry Chance | L13: =622/19130+0.03+(L6+L8)/((L6+L8)*1+1/0.94)+0.05*8*T28 -> 0.26392296 | N13: Performance Measures
B14: Base Weapon DPS | C14: =IF(ISBLANK(Inputs!H16),Inputs!C16+Inputs!I16,Inputs!H16) -> 151.4 | G14: Dodge | H14: =0.03+0.02*C32 -> 0.03 | I14: Misc. Damage Done Multiplier | J14: =(1+E30*0.05*(1.13*(1-exp(-1*J9*15/60))))*(1+C57*0.06*(1-0.85^(5/(3/((1/(1-0.15*C107))*(1+C130))))))*(1+C117*0.05)*IF(D100=2,(1+0.06*C119*(1-T40*(1-(0.75)^((5+(H15/2))/H15))/(1+3*(1-(0.75)^((5+(H15/2))/H15))*C82)/(1-(0.75)^((5+(H15/2))/H15)))),(1+0.06*(14-5*C131*E137)*C119*(1/S40)))*(1+IF(C127>2,2,IF(C127=2,1,0))*0.03*E127) -> 1.1864675 | K14: Attack Avoidance Chance | L14: =MAX(L13-0.015*(C153-90),0)+MAX(H14-0.015*(C153-90),0)+MAX(0.03-0.015*(C153-90),0) -> 0.32392296 | N14: Mitigation Factor | O14: Overall DPS | P14: Priority DPS | Q14: Reliable EHP | R14: Reliable and Controllable EHP | S14: Unreliable EHP
